Workbook

Sheet Variables 
A3: Nº individuo | B3: Nº individuo que realiza la encuesta
A4: Sexo | B4: Sexo ( "Hombre"; "Mujer")
A5: Estatura | B5: Estatura en cm
A6: Peso | B6: Peso en Kg
A7: Deporte | B7: Frecuencia con la que practica deporte ("Nunca"; Ocasionalmente (menos de una vez por semana); "Regularmente (1 ó 2 veces por semana); "Frecuentemente (3 a 4 veces a la semana)"; "Muy frecuentemente (5 o más veces a la semana")
A8: Hermanos | B8: Nº hermanos (incluido el alumno)
A9: Residencia | B9: Lugar de residencia familiar ("Zaragoza capital"; "Zaragoza provincia (excepto Zaragoza capital)"; "Aragón (provincias de Huesca o Teruel)"; "Fuera de Aragón")
A10: Centro | B10: Tipo de centro en el que ha realizado los estudios a través de los que ha accedido a la Universidad (bachillerato, FP,...) ( "Público"; "Concertado/Privado")
A11: Nota Bach. | B11: Nota media del bachillerato (sobre 10)
A12: Nota Sel. | B12: Nota global de la selectividad (sobre 14)
A13: Ordenador | B13: Dispone de ordenador personal ( "SI"; "NO")
A14: ADSL | B14: Dispone de banda ancha (ADSL, Fibra,…) ("SI"; "NO")
... A16: Horasred | B16: Nº horas semanales actividad en redes sociales
A18: Variables auxiliares
A19: Sexo(num) | B19: 0 = Mujer 1 = Hombre
A20: Deporte(num) | B20: 0 = Nunca 1 = Ocasionalmente 2 = Regularmente 3 = Frecuentemente 4 = Muy frecuentemente
A21: Residencia(num) | B21: 0 = Zaragoza capital 1 = Zaragoza provincia 2 = Aragón 3 = Fuera de Aragón
A22: Centro(num) | B22: 0 = Público 1 = Concertado
A23: Ordenador(num) | B23: 0 = No 1 = Sí
A24: ADSL(num) | B24: 0 = No 1 = Sí
A25: RedSocial(num) | B25: 0 = No 1 = Sí

Sheet Datos 
A1: Número | B1: Sexo | C1: Estatura | D1: Peso | E1: Deporte | F1: Hermanos | G1: Residencia | H1: Centro | I1: Nota.Bach. | J1: Nota global | K1: Ordenador | L1: ADSL | M1: Red Social | N1: Horasred
A2: 1 | B2: Hombre | C2: 0 | D2: 0 | E2: Ocasionalmente (menos de 1 vez a la semana) | F2: 0 | G2: Fuera de Aragón | H2: Público | I2: 0 | J2: 0 | K2: Sí | L2: Sí | M2: Sí | N2: 0
A3: 2 | B3: Hombre | C3: 0 | D3: 0 | E3: Frecuentemente (3 o 4 veces a la semana) | F3: 0 | G3: Zaragoza capital | H3: Concertado/Privado | I3: 0 | J3: 0 | K3: Sí | L3: Sí | M3: Sí | N3: 0
A4: 3 | B4: Hombre | C4: 0 | D4: 0 | E4: Frecuentemente (3 o 4 veces a la semana) | F4: 0 | G4: Aragón (provincias de Huesca o Teruel) | H4: Público | I4: 0 | J4: 0 | K4: Sí | L4: No | M4: Sí | N4: 0
A5: 4 | B5: Mujer | C5: 162 | D5: 52.5 | E5: Regularmente (1 o 2 veces a la semana) | F5: 4 | G5: Zaragoza capital | H5: Público | I5: 9 | J5: 11 | K5: Sí | L5: Sí | M5: No | N5: 0
A6: 5 | B6: Hombre | C6: 182 | D6: 76 | E6: Frecuentemente (3 o 4 veces a la semana) | F6: 2 | G6: Aragón (provincias de Huesca o Teruel) | H6: Público | I6: 7 | J6: 7 | K6: Sí | L6: Sí | M6: Sí | N6: 10
A7: 6 | B7: Hombre | C7: 185 | D7: 84 | E7: Muy frecuentemente (5 veces a la semana o más) | F7: 2 | G7: Zaragoza capital | H7: Público | I7: 6 | J7: 0 | K7: Sí | L7: Sí | M7: Sí | N7: 2
A8: 7 | B8: Hombre | C8: 170 | D8: 60 | E8: Ocasionalmente (menos de 1 vez a la semana) | F8: 3 | G8: Zaragoza capital | H8: Público | I8: 8 | J8: 8 | K8: Sí | L8: Sí | M8: Sí | N8: 30
A9: 8 | B9: Mujer | C9: 172 | D9: 72 | E9: Regularmente (1 o 2 veces a la semana) | F9: 2 | G9: Zaragoza provincia (excepto Zaragoza capital) | H9: Público | I9: 6.9 | J9: 8.9 | K9: Sí | L9: Sí | M9: Sí | N9: 3
A10: 9 | B10: Mujer | C10: 159 | D10: 51 | E10: Ocasionalmente (menos de 1 vez a la semana) | F10: 2 | G10: Zaragoza capital | H10: Público | I10: 7.3 | J10: 7.5 | N10: 0
A11: 10 | B11: Hombre | C11: 182 | D11: 76 | E11: Frecuentemente (3 o 4 veces a la semana) | F11: 2 | G11: Zaragoza provincia (excepto Zaragoza capital) | H11: Público | I11: 5.58 | J11: 5.2 | K11: Sí | L11: Sí | M11: Sí | N11: 8
A12: 11 | B12: Mujer | C12: 1.6 | D12: 50 | E12: Ocasionalmente (menos de 1 vez a la semana) | F12: 2 | G12: Zaragoza provincia (excepto Zaragoza capital) | H12: Público | I12: 6 | J12: 7.6 | K12: Sí | L12: Sí | M12: No | N12: 0
A13: 12 | B13: Hombre | C13: 182 | D13: 65 | E13: Frecuentemente (3 o 4 veces a la semana) | F13: 3 | G13: Zaragoza capital | H13: Público | I13: 7.5 | J13: 9.303 | K13: Sí | L13: Sí | M13: Sí | N13: 10
A14: 13 | B14: Hombre | C14: 180 | D14: 71 | E14: Frecuentemente (3 o 4 veces a la semana) | F14: 1 | G14: Zaragoza capital | H14: Concertado/Privado | I14: 5.5 | J14: 5.9 | K14: Sí | L14: Sí | M14: Sí | N14: 20
A15: 14 | B15: Hombre | C15: 178 | D15: 76 | E15: Muy frecuentemente (5 veces a la semana o más) | F15: 2 | G15: Zaragoza capital | H15: Concertado/Privado | I15: 5.6 | J15: 6.8 | K15: Sí | L15: Sí | M15: Sí | N15: 7
A16: 15 | B16: Mujer | C16: 163 | D16: 50 | E16: Nunca | F16: 2 | G16: Zaragoza capital | H16: Público | I16: 6 | J16: 7 | K16: Sí | L16: Sí | M16: Sí | N16: 5
A17: 16 | B17: Hombre | C17: 173 | D17: 69 | E17: Nunca | F17: 2 | G17: Zaragoza capital | H17: Concertado/Privado | I17: 7.5 | J17: 7.4 | K17: Sí | L17: Sí | M17: Sí | N17: 35
A18: 17 | B18: Mujer | C18: 160 | D18: 50 | E18: Ocasionalmente (menos de 1 vez a la semana) | F18: 2 | G18: Zaragoza capital | H18: Público | I18: 6 | J18: 6 | K18: No | L18: Sí | M18: Sí | N18: 1
A19: 18 | B19: Hombre | C19: 184 | D19: 68 | E19: Frecuentemente (3 o 4 veces a la semana) | F19: 2 | G19: Zaragoza capital | H19: Público | I19: 6.2 | J19: 8 | K19: Sí | L19: Sí | M19: Sí | N19: 4
A20: 19 | B20: Mujer | C20: 162 | D20: 57 | E20: Ocasionalmente (menos de 1 vez a la semana) | F20: 3 | G20: Zaragoza capital | H20: Concertado/Privado | I20: 6.8 | J20: 6.5 | K20: Sí | L20: Sí | M20: Sí | N20: 4
A21: 20 | B21: Mujer | C21: 165 | D21: 56 | E21: Regularmente (1 o 2 veces a la semana) | F21: 3 | G21: Aragón (provincias de Huesca o Teruel) | H21: Público | I21: 8.5 | J21: 10.5 | K21: Sí | L21: Sí | M21: Sí | N21: 14
A22: 21 | B22: Mujer | C22: 165 | D22: 50 | E22: Ocasionalmente (menos de 1 vez a la semana) | F22: 3 | G22: Aragón (provincias de Huesca o Teruel) | H22: Público | I22: 9.5 | J22: 12.1 | K22: Sí | L22: Sí | M22: Sí | N22: 14
... A25: 24 | B25: Mujer | C25: 167 | D25: 61 | E25: Regularmente (1 o 2 veces a la semana) | F25: 3 | G25: Zaragoza capital | H25: Concertado/Privado | I25: 6.6 | J25: 8.2 | K25: Sí | L25: Sí | M25: Sí | N25: 14
A26: 25 | B26: Hombre | C26: 1.74 | D26: 59.8 | E26: Regularmente (1 o 2 veces a la semana) | F26: 2 | G26: Zaragoza capital | I26: 7.56 | J26: 9.72 | K26: Sí | L26: Sí | M26: Sí | N26: 2.6
A27: 26 | B27: Hombre | C27: 173 | D27: 73 | E27: Frecuentemente (3 o 4 veces a la semana) | F27: 0 | G27: Zaragoza capital | H27: Concertado/Privado | I27: 6.5 | J27: 6.375 | K27: Sí | L27: Sí | M27: Sí | N27: 25
A28: 27 | B28: Hombre | C28: 171 | D28: 66 | E28: Regularmente (1 o 2 veces a la semana) | F28: 2 | G28: Zaragoza provincia (excepto Zaragoza capital) | H28: Público | I28: 6.7 | J28: 8.73 | K28: Sí | L28: Sí | M28: Sí | N28: 15
A29: 28 | B29: Hombre | C29: 177 | D29: 65 | E29: Regularmente (1 o 2 veces a la semana) | F29: 2 | G29: Zaragoza capital | H29: Concertado/Privado | I29: 6 | J29: 8 | K29: Sí | L29: Sí | M29: Sí | N29: 5
A30: 29 | B30: Mujer | C30: 170 | D30: 59 | E30: Regularmente (1 o 2 veces a la semana) | F30: 2 | G30: Zaragoza capital | H30: Concertado/Privado | I30: 7 | J30: 8.235 | K30: No | L30: Sí | M30: Sí | N30: 3
A31: 30 | B31: Mujer | C31: 163.5 | D31: 42.5 | E31: Muy frecuentemente (5 veces a la semana o más) | F31: 1 | G31: Aragón (provincias de Huesca o Teruel) | H31: Público | I31: 9.9 | J31: 12.5 | K31: Sí | L31: Sí | M31: Sí | N31: 8
A32: 31 | B32: Mujer | C32: 150 | D32: 45 | E32: Ocasionalmente (menos de 1 vez a la semana) | F32: 2 | G32: Zaragoza capital | H32: Público | I32: 6.5 | J32: 7.5 | K32: Sí | L32: Sí | M32: Sí | N32: 21
A33: 32 | B33: Hombre | C33: 175 | D33: 65 | E33: Frecuentemente (3 o 4 veces a la semana) | F33: 2 | G33: Zaragoza capital | H33: Público | I33: 7 | J33: 9 | K33: Sí | L33: Sí | M33: Sí | N33: 30
A34: 33 | B34: Hombre | C34: 180 | D34: 70 | E34: Ocasionalmente (menos de 1 vez a la semana) | F34: 2 | G34: Zaragoza provincia (excepto Zaragoza capital) | H34: Público | I34: 7 | J34: 7 | K34: Sí | L34: Sí | M34: Sí | N34: 3
A35: 34 | B35: Hombre | C35: 185 | D35: 0 | F35: 0 | I35: 0 | J35: 0 | N35: 0
A36: 35 | B36: Hombre | C36: 172 | D36: 67 | E36: Regularmente (1 o 2 veces a la semana) | F36: 2 | G36: Zaragoza capital | H36: Concertado/Privado | I36: 5.5 | J36: 5.2 | K36: Sí | L36: Sí | M36: Sí | N36: 15
A37: 36 | B37: Mujer | C37: 185 | D37: 85 | E37: Regularmente (1 o 2 veces a la semana) | F37: 2 | G37: Aragón (provincias de Huesca o Teruel) | H37: Público | I37: 8.4 | J37: 8.9 | K37: Sí | L37: Sí | M37: Sí | N37: 5
A38: 37 | B38: Mujer | C38: 167 | D38: 48 | E38: Ocasionalmente (menos de 1 vez a la semana) | F38: 2 | G38: Zaragoza capital | H38: Público | I38: 6.21 | J38: 8.1 | K38: Sí | L38: Sí | M38: Sí | N38: 10
A39: 38 | B39: Mujer | C39: 165 | D39: 57 | E39: Ocasionalmente (menos de 1 vez a la semana) | F39: 3 | G39: Zaragoza capital | H39: Público | I39: 5.6 | J39: 7.9 | K39: Sí | L39: Sí | M39: Sí | N39: 10
A40: 39 | B40: Mujer | C40: 165 | D40: 58 | E40: Regularmente (1 o 2 veces a la semana) | F40: 3 | G40: Zaragoza capital | H40: Público | I40: 6.1 | J40: 6.69 | K40: Sí | L40: Sí | M40: Sí | N40: 10
A41: 40 | B41: Mujer | C41: 163 | D41: 58 | E41: Regularmente (1 o 2 veces a la semana) | F41: 3 | G41: Zaragoza capital | H41: Público | I41: 7.8 | J41: 10.9 | K41: Sí | L41: Sí | M41: Sí | N41: 15
A42: 41 | B42: Hombre | C42: 183 | D42: 78 | E42: Muy frecuentemente (5 veces a la semana o más) | F42: 1 | G42: Zaragoza capital | H42: Concertado/Privado | I42: 7.1 | J42: 9.2 | K42: Sí | L42: Sí | M42: Sí | N42: 35
...

Sheet Datos depurados
A1: Número | B1: Sexo(num) | C1: Sexo | D1: Estatura | E1: Peso | F1: Deporte(num) | G1: Deporte | H1: Hermanos | I1: Residencia(num) | J1: Residencia | K1: Centro(num) | L1: Centro | M1: Nota.Bach. | N1: Notaglobal | O1: Ordenador(num) | P1: Ordenador | Q1: ADSL(num) | R1: ADSL | S1: RedSocial(num) | T1: RedSocial | U1: Horasred
A2: 1 | B2: 1 | C2: Hombre | F2: 1 | G2: Ocasionalmente (menos de 1 vez a la semana) | I2: 3 | J2: Fuera de Aragón | K2: 0 | L2: Público | O2: 1 | P2: Sí | Q2: 1 | R2: Sí | S2: 1 | T2: Sí
A3: 2 | B3: 1 | C3: Hombre | F3: 3 | G3: Frecuentemente (3 o 4 veces a la semana) | I3: 0 | J3: Zaragoza capital | K3: 1 | L3: Concertado/Privado | O3: 1 | P3: Sí | Q3: 1 | R3: Sí | S3: 1 | T3: Sí
A4: 3 | B4: 1 | C4: Hombre | F4: 3 | G4: Frecuentemente (3 o 4 veces a la semana) | I4: 2 | J4: Aragón (provincias de Huesca o Teruel) | K4: 0 | L4: Público | O4: 1 | P4: Sí | Q4: 0 | R4: No | S4: 1 | T4: Sí
A5: 4 | B5: 0 | C5: Mujer | D5: 162 | E5: 52.5 | F5: 2 | G5: Regularmente (1 o 2 veces a la semana) | H5: 4 | I5: 0 | J5: Zaragoza capital | K5: 0 | L5: Público | M5: 9 | N5: 11 | O5: 1 | P5: Sí | Q5: 1 | R5: Sí | S5: 0 | T5: No | U5: 0
A6: 5 | B6: 1 | C6: Hombre | D6: 182 | E6: 76 | F6: 3 | G6: Frecuentemente (3 o 4 veces a la semana) | H6: 2 | I6: 2 | J6: Aragón (provincias de Huesca o Teruel) | K6: 0 | L6: Público | M6: 7 | N6: 7 | O6: 1 | P6: Sí | Q6: 1 | R6: Sí | S6: 1 | T6: Sí | U6: 10
A7: 6 | B7: 1 | C7: Hombre | D7: 185 | E7: 84 | F7: 4 | G7: Muy frecuentemente (5 veces a la semana o más) | H7: 2 | I7: 0 | J7: Zaragoza capital | K7: 0 | L7: Público | M7: 6 | O7: 1 | P7: Sí | Q7: 1 | R7: Sí | S7: 1 | T7: Sí | U7: 2
A8: 7 | B8: 1 | C8: Hombre | D8: 170 | E8: 60 | F8: 1 | G8: Ocasionalmente (menos de 1 vez a la semana) | H8: 3 | I8: 0 | J8: Zaragoza capital | K8: 0 | L8: Público | M8: 8 | N8: 8 | O8: 1 | P8: Sí | Q8: 1 | R8: Sí | S8: 1 | T8: Sí | U8: 30
A9: 8 | B9: 0 | C9: Mujer | D9: 172 | E9: 72 | F9: 2 | G9: Regularmente (1 o 2 veces a la semana) | H9: 2 | I9: 1 | J9: Zaragoza provincia (excepto Zaragoza capital) | K9: 0 | L9: Público | M9: 6.9 | N9: 8.9 | O9: 1 | P9: Sí | Q9: 1 | R9: Sí | S9: 1 | T9: Sí | U9: 3
A10: 9 | B10: 0 | C10: Mujer | D10: 159 | E10: 51 | F10: 1 | G10: Ocasionalmente (menos de 1 vez a la semana) | H10: 2 | I10: 0 | J10: Zaragoza capital | K10: 0 | L10: Público | M10: 7.3 | N10: 7.5
A11: 10 | B11: 1 | C11: Hombre | D11: 182 | E11: 76 | F11: 3 | G11: Frecuentemente (3 o 4 veces a la semana) | H11: 2 | I11: 1 | J11: Zaragoza provincia (excepto Zaragoza capital) | K11: 0 | L11: Público | M11: 5.58 | N11: 5.2 | O11: 1 | P11: Sí | Q11: 1 | R11: Sí | S11: 1 | T11: Sí | U11: 8
A12: 11 | B12: 0 | C12: Mujer | D12: 160 | E12: 50 | F12: 1 | G12: Ocasionalmente (menos de 1 vez a la semana) | H12: 2 | I12: 1 | J12: Zaragoza provincia (excepto Zaragoza capital) | K12: 0 | L12: Público | M12: 6 | N12: 7.6 | O12: 1 | P12: Sí | Q12: 1 | R12: Sí | S12: 0 | T12: No | U12: 0
A13: 12 | B13: 1 | C13: Hombre | D13: 182 | E13: 65 | F13: 3 | G13: Frecuentemente (3 o 4 veces a la semana) | H13: 3 | I13: 0 | J13: Zaragoza capital | K13: 0 | L13: Público | M13: 7.5 | N13: 9.303 | O13: 1 | P13: Sí | Q13: 1 | R13: Sí | S13: 1 | T13: Sí | U13: 10
A14: 13 | B14: 1 | C14: Hombre | D14: 180 | E14: 71 | F14: 3 | G14: Frecuentemente (3 o 4 veces a la semana) | H14: 1 | I14: 0 | J14: Zaragoza capital | K14: 1 | L14: Concertado/Privado | M14: 5.5 | N14: 5.9 | O14: 1 | P14: Sí | Q14: 1 | R14: Sí | S14: 1 | T14: Sí | U14: 20
A15: 14 | B15: 1 | C15: Hombre | D15: 178 | E15: 76 | F15: 4 | G15: Muy frecuentemente (5 veces a la semana o más) | H15: 2 | I15: 0 | J15: Zaragoza capital | K15: 1 | L15: Concertado/Privado | M15: 5.6 | N15: 6.8 | O15: 1 | P15: Sí | Q15: 1 | R15: Sí | S15: 1 | T15: Sí | U15: 7
A16: 15 | B16: 0 | C16: Mujer | D16: 163 | E16: 50 | F16: 0 | G16: Nunca | H16: 2 | I16: 0 | J16: Zaragoza capital | K16: 0 | L16: Público | M16: 6 | N16: 7 | O16: 1 | P16: Sí | Q16: 1 | R16: Sí | S16: 1 | T16: Sí | U16: 5
A17: 16 | B17: 1 | C17: Hombre | D17: 173 | E17: 69 | F17: 0 | G17: Nunca | H17: 2 | I17: 0 | J17: Zaragoza capital | K17: 1 | L17: Concertado/Privado | M17: 7.5 | N17: 7.4 | O17: 1 | P17: Sí | Q17: 1 | R17: Sí | S17: 1 | T17: Sí | U17: 35
A18: 17 | B18: 0 | C18: Mujer | D18: 160 | E18: 50 | F18: 1 | G18: Ocasionalmente (menos de 1 vez a la semana) | H18: 2 | I18: 0 | J18: Zaragoza capital | K18: 0 | L18: Público | M18: 6 | N18: 6 | O18: 0 | P18: No | Q18: 1 | R18: Sí | S18: 1 | T18: Sí | U18: 1
A19: 18 | B19: 1 | C19: Hombre | D19: 184 | E19: 68 | F19: 3 | G19: Frecuentemente (3 o 4 veces a la semana) | H19: 2 | I19: 0 | J19: Zaragoza capital | K19: 0 | L19: Público | M19: 6.2 | N19: 8 | O19: 1 | P19: Sí | Q19: 1 | R19: Sí | S19: 1 | T19: Sí | U19: 4
A20: 19 | B20: 0 | C20: Mujer | D20: 162 | E20: 57 | F20: 1 | G20: Ocasionalmente (menos de 1 vez a la semana) | H20: 3 | I20: 0 | J20: Zaragoza capital | K20: 1 | L20: Concertado/Privado | M20: 6.8 | N20: 6.5 | O20: 1 | P20: Sí | Q20: 1 | R20: Sí | S20: 1 | T20: Sí | U20: 4
A21: 20 | B21: 0 | C21: Mujer | D21: 165 | E21: 56 | F21: 2 | G21: Regularmente (1 o 2 veces a la semana) | H21: 3 | I21: 2 | J21: Aragón (provincias de Huesca o Teruel) | K21: 0 | L21: Público | M21: 8.5 | N21: 10.5 | O21: 1 | P21: Sí | Q21: 1 | R21: Sí | S21: 1 | T21: Sí | U21: 14
A22: 21 | B22: 0 | C22: Mujer | D22: 165 | E22: 50 | F22: 1 | G22: Ocasionalmente (menos de 1 vez a la semana) | H22: 3 | I22: 2 | J22: Aragón (provincias de Huesca o Teruel) | K22: 0 | L22: Público | M22: 9.5 | N22: 12.1 | O22: 1 | P22: Sí | Q22: 1 | R22: Sí | S22: 1 | T22: Sí | U22: 14
A23: 22 | B23: 1 | C23: Hombre | D23: 172 | E23: 60 | F23: 2 | G23: Regularmente (1 o 2 veces a la semana) | I23: 2 | J23: Aragón (provincias de Huesca o Teruel) | K23: 1 | L23: Concertado/Privado | M23: 7 | N23: 7.8 | O23: 1 | P23: Sí | Q23: 1 | R23: Sí | S23: 1 | T23: Sí | U23: 20
A24: 23 | B24: 0 | C24: Mujer | D24: 173 | E24: 59 | F24: 3 | G24: Frecuentemente (3 o 4 veces a la semana) | H24: 2 | I24: 0 | J24: Zaragoza capital | K24: 0 | L24: Público | M24: 9.2 | N24: 10.5 | O24: 1 | P24: Sí | Q24: 1 | R24: Sí | S24: 1 | T24: Sí | U24: 6
A25: 24 | B25: 0 | C25: Mujer | D25: 167 | E25: 61 | F25: 2 | G25: Regularmente (1 o 2 veces a la semana) | H25: 3 | I25: 0 | J25: Zaragoza capital | K25: 1 | L25: Concertado/Privado | M25: 6.6 | N25: 8.2 | O25: 1 | P25: Sí | Q25: 1 | R25: Sí | S25: 1 | T25: Sí | U25: 14
A26: 25 | B26: 1 | C26: Hombre | D26: 174 | E26: 59.8 | F26: 2 | G26: Regularmente (1 o 2 veces a la semana) | H26: 2 | I26: 0 | J26: Zaragoza capital | M26: 7.56 | N26: 9.72 | O26: 1 | P26: Sí | Q26: 1 | R26: Sí | S26: 1 | T26: Sí | U26: 2.6
A27: 26 | B27: 1 | C27: Hombre | D27: 173 | E27: 73 | F27: 3 | G27: Frecuentemente (3 o 4 veces a la semana) | I27: 0 | J27: Zaragoza capital | K27: 1 | L27: Concertado/Privado | M27: 6.5 | N27: 6.375 | O27: 1 | P27: Sí | Q27: 1 | R27: Sí | S27: 1 | T27: Sí | U27: 25
A28: 27 | B28: 1 | C28: Hombre | D28: 171 | E28: 66 | F28: 2 | G28: Regularmente (1 o 2 veces a la semana) | H28: 2 | I28: 1 | J28: Zaragoza provincia (excepto Zaragoza capital) | K28: 0 | L28: Público | M28: 6.7 | N28: 8.73 | O28: 1 | P28: Sí | Q28: 1 | R28: Sí | S28: 1 | T28: Sí | U28: 15
A29: 28 | B29: 1 | C29: Hombre | D29: 177 | E29: 65 | F29: 2 | G29: Regularmente (1 o 2 veces a la semana) | H29: 2 | I29: 0 | J29: Zaragoza capital | K29: 1 | L29: Concertado/Privado | M29: 6 | N29: 8 | O29: 1 | P29: Sí | Q29: 1 | R29: Sí | S29: 1 | T29: Sí | U29: 5
A30: 29 | B30: 0 | C30: Mujer | D30: 170 | E30: 59 | F30: 2 | G30: Regularmente (1 o 2 veces a la semana) | H30: 2 | I30: 0 | J30: Zaragoza capital | K30: 1 | L30: Concertado/Privado | M30: 7 | N30: 8.235 | O30: 0 | P30: No | Q30: 1 | R30: Sí | S30: 1 | T30: Sí | U30: 3
A31: 30 | B31: 0 | C31: Mujer | D31: 163.5 | E31: 42.5 | F31: 4 | G31: Muy frecuentemente (5 veces a la semana o más) | H31: 1 | I31: 2 | J31: Aragón (provincias de Huesca o Teruel) | K31: 0 | L31: Público | M31: 9.9 | N31: 12.5 | O31: 1 | P31: Sí | Q31: 1 | R31: Sí | S31: 1 | T31: Sí | U31: 8
A32: 31 | B32: 0 | C32: Mujer | D32: 150 | E32: 45 | F32: 1 | G32: Ocasionalmente (menos de 1 vez a la semana) | H32: 2 | I32: 0 | J32: Zaragoza capital | K32: 0 | L32: Público | M32: 6.5 | N32: 7.5 | O32: 1 | P32: Sí | Q32: 1 | R32: Sí | S32: 1 | T32: Sí | U32: 21
A33: 32 | B33: 1 | C33: Hombre | D33: 175 | E33: 65 | F33: 3 | G33: Frecuentemente (3 o 4 veces a la semana) | H33: 2 | I33: 0 | J33: Zaragoza capital | K33: 0 | L33: Público | M33: 7 | N33: 9 | O33: 1 | P33: Sí | Q33: 1 | R33: Sí | S33: 1 | T33: Sí | U33: 30
A34: 33 | B34: 1 | C34: Hombre | D34: 180 | E34: 70 | F34: 1 | G34: Ocasionalmente (menos de 1 vez a la semana) | H34: 2 | I34: 1 | J34: Zaragoza provincia (excepto Zaragoza capital) | K34: 0 | L34: Público | M34: 7 | N34: 7 | O34: 1 | P34: Sí | Q34: 1 | R34: Sí | S34: 1 | T34: Sí | U34: 3
A35: 34 | B35: 1 | C35: Hombre | D35: 185
A36: 35 | B36: 1 | C36: Hombre | D36: 172 | E36: 67 | F36: 2 | G36: Regularmente (1 o 2 veces a la semana) | H36: 2 | I36: 0 | J36: Zaragoza capital | K36: 1 | L36: Concertado/Privado | M36: 5.5 | N36: 5.2 | O36: 1 | P36: Sí | Q36: 1 | R36: Sí | S36: 1 | T36: Sí | U36: 15
A37: 36 | B37: 0 | C37: Mujer | D37: 185 | E37: 85 | F37: 2 | G37: Regularmente (1 o 2 veces a la semana) | H37: 2 | I37: 2 | J37: Aragón (provincias de Huesca o Teruel) | K37: 0 | L37: Público | M37: 8.4 | N37: 8.9 | O37: 1 | P37: Sí | Q37: 1 | R37: Sí | S37: 1 | T37: Sí | U37: 5
A38: 37 | B38: 0 | C38: Mujer | D38: 167 | E38: 48 | F38: 1 | G38: Ocasionalmente (menos de 1 vez a la semana) | H38: 2 | I38: 0 | J38: Zaragoza capital | K38: 0 | L38: Público | M38: 6.21 | N38: 8.1 | O38: 1 | P38: Sí | Q38: 1 | R38: Sí | S38: 1 | T38: Sí | U38: 10
A39: 38 | B39: 0 | C39: Mujer | D39: 165 | E39: 57 | F39: 1 | G39: Ocasionalmente (menos de 1 vez a la semana) | H39: 3 | I39: 0 | J39: Zaragoza capital | K39: 0 | L39: Público | M39: 5.6 | N39: 7.9 | O39: 1 | P39: Sí | Q39: 1 | R39: Sí | S39: 1 | T39: Sí | U39: 10
A40: 39 | B40: 0 | C40: Mujer | D40: 165 | E40: 58 | F40: 2 | G40: Regularmente (1 o 2 veces a la semana) | H40: 3 | I40: 0 | J40: Zaragoza capital | K40: 0 | L40: Público | M40: 6.1 | N40: 6.69 | O40: 1 | P40: Sí | Q40: 1 | R40: Sí | S40: 1 | T40: Sí | U40: 10
...

Sheet Lugar de residencia familiar
B4: X:Lugar de residencia familiar | C4: xi | D4: ni | E4: fi | F4: %
B5: Zaragoza capital | C5: 0 | D5: =COUNTIF('Datos depurados'!I:I,0) -> 79 | E5: =D5/$D$9 -> 0.56834532 | F5: =E5 -> 0.56834532
B6: Zaragoza provincia (excepto Zaragoza capital) | C6: 1 | D6: =COUNTIF('Datos depurados'!I:I,1) -> 15 | E6: =D6/$D$9 -> 0.10791367 | F6: =E6 -> 0.10791367
B7: Aragón (provincias de Huesca o Teruel) | C7: 2 | D7: =COUNTIF('Datos depurados'!I:I,2) -> 24 | E7: =D7/$D$9 -> 0.17266187 | F7: =E7 -> 0.17266187
B8: Fuera de Aragón | C8: 3 | D8: =COUNTIF('Datos depurados'!I:I,3) -> 21 | E8: =D8/$D$9 -> 0.15107914 | F8: =E8 -> 0.15107914
B9: Total | D9: =SUM(D5:D8) -> 139 | E9: =SUM(E5:E8) -> 1 | F9: =SUM(F5:F8) -> 1
B11: Ausentes | C11: 3

Sheet Número de hermanos
B2: MÍNIMO | C2: =MIN('Datos depurados'!$H$2:$H$143) -> 1
B3: MÁXIMO | C3: =MAX('Datos depurados'!$H$2:$H$143) -> 6
B5: xi | C5: ni | D5: fi | E5: Ni | F5: Fi
B6: 1 | C6: =COUNTIF('Datos depurados'!H:H,B6) -> 20 | D6: =C6/$C$12 -> 0.15748032 | E6: =C6 -> 20 | F6: =E6/$C$12 -> 0.15748032
B7: 2 | C7: =COUNTIF('Datos depurados'!H:H,B7) -> 71 | D7: =C7/$C$12 -> 0.55905512 | E7: =C7+E6 -> 91 | F7: =E7/$C$12 -> 0.71653543
B8: 3 | C8: =COUNTIF('Datos depurados'!H:H,B8) -> 30 | D8: =C8/$C$12 -> 0.23622047 | E8: =C8+E7 -> 121 | F8: =E8/$C$12 -> 0.95275591
B9: 4 | C9: =COUNTIF('Datos depurados'!H:H,B9) -> 2 | D9: =C9/$C$12 -> 0.015748031 | E9: =C9+E8 -> 123 | F9: =E9/$C$12 -> 0.96850394
B10: 5 | C10: =COUNTIF('Datos depurados'!H:H,B10) -> 2 | D10: =C10/$C$12 -> 0.015748031 | E10: =C10+E9 -> 125 | F10: =E10/$C$12 -> 0.98425197
B11: 6 | C11: =COUNTIF('Datos depurados'!H:H,B11) -> 2 | D11: =C11/$C$12 -> 0.015748031 | E11: =C11+E10 -> 127 | F11: =E11/$C$12 -> 1
B12: Total | C12: =SUM(C6:C11) -> 127 | D12: =C12/$C$12 -> 1
B13: Ausentes | C13: 15 | D13: =C13/$C$12 -> 0.11811024

Sheet Estaturas
A3: Sexo | B3: Estatura | C3: Sexo | D3: Estatura | F3: Mínimo | G3: =min(D:D) -> 150 | I3: Hay 3 personas menos porque se han quitado los que en "datos depurados"
A4: Hombre | B4: 182 | C4: Mujer | D4: 162 | F4: Máximo | G4: =max(D:D) -> 187 | I4: no sabemos si son hombres o mujeres
A5: Hombre | B5: 185 | C5: Mujer | D5: 172 | F5: Límite inf | G5: 150
A6: Hombre | B6: 170 | C6: Mujer | D6: 159 | F6: Límite sup | G6: 195
A7: Hombre | B7: 182 | C7: Mujer | D7: 160 | F7: Nº intervalos | G7: =(G6-G5)/5 -> 9
A8: Hombre | B8: 182 | C8: Mujer | D8: 163 | F8: Amplitud | G8: 5
A9: Hombre | B9: 180 | C9: Mujer | D9: 160
A10: Hombre | B10: 178 | C10: Mujer | D10: 162
A11: Hombre | B11: 173 | C11: Mujer | D11: 165
A12: Hombre | B12: 184 | C12: Mujer | D12: 165 | F12: Li-1 | G12: Li | H12: xi | I12: ni (todos) | J12: ni (alumnos) | K12: ni (alumnas) | L12: fi (todos) | M12: fi (alumnos) | N12: fi (alumnas) | O12: Fi (todos) | P12: Fi(alumnos) | Q12: Fi (alumnas)
A13: Hombre | B13: 172 | C13: Mujer | D13: 173 | F13: =G3 -> 150 | G13: =F13+5 -> 155 | H13: =(F13+G13)/2 -> 152.5 | I13: =SUM(J13:K13) -> 2 | J13: =COUNTIFS(B4:B86,">=150",B4:B86,"<155") -> 0 | K13: =COUNTIFS(D4:D86,">=150",D4:D86,"<155") -> 2 | L13: =I13/$I$22 -> 0.014705882 | M13: =J13/$J$22 -> 0 | N13: =K13/$K$22 -> 0.037735849 | O13: =L13 -> 0.014705882 | P13: =M13 -> 0 | Q13: =N13 -> 0.037735849
A14: Hombre | B14: 174 | C14: Mujer | D14: 167 | F14: =G13 -> 155 | G14: =F14+5 -> 160 | H14: =(F14+G14)/2 -> 157.5 | I14: =SUM(J14:K14) -> 4 | J14: =COUNTIFS(B4:B86,">=155",B4:B86,"<160") -> 1 | K14: =COUNTIFS(D4:D86,">=155",D4:D86,"<160") -> 3 | L14: =I14/$I$22 -> 0.029411765 | M14: =J14/$J$22 -> 0.012048193 | N14: =K14/$K$22 -> 0.056603774 | O14: =O13+L14 -> 0.044117647 | P14: =P13+M14 -> 0.012048193 | Q14: =Q13+N14 -> 0.094339623
A15: Hombre | B15: 173 | C15: Mujer | D15: 170 | F15: =G14 -> 160 | G15: =F15+5 -> 165 | H15: =(F15+G15)/2 -> 162.5 | I15: =SUM(J15:K15) -> 16 | J15: =COUNTIFS(B4:B86,">=160",B4:B86,"<165") -> 1 | K15: =COUNTIFS(D4:D86,">=160",D4:D86,"<165") -> 15 | L15: =I15/$I$22 -> 0.11764706 | M15: =J15/$J$22 -> 0.012048193 | N15: =K15/$K$22 -> 0.28301887 | O15: =O14+L15 -> 0.16176471 | P15: =P14+M15 -> 0.024096386 | Q15: =Q14+N15 -> 0.37735849
A16: Hombre | B16: 171 | C16: Mujer | D16: 163.5 | F16: =G15 -> 165 | G16: =F16+5 -> 170 | H16: =(F16+G16)/2 -> 167.5 | I16: =SUM(J16:K16) -> 27 | J16: =COUNTIFS(B4:B86,">=165",B4:B86,"<170") -> 7 | K16: =COUNTIFS(D4:D86,">=165",D4:D86,"<170") -> 20 | L16: =I16/$I$22 -> 0.19852941 | M16: =J16/$J$22 -> 0.084337349 | N16: =K16/$K$22 -> 0.37735849 | O16: =O15+L16 -> 0.36029412 | P16: =P15+M16 -> 0.10843373 | Q16: =Q15+N16 -> 0.75471698
A17: Hombre | B17: 177 | C17: Mujer | D17: 150 | F17: =G16 -> 170 | G17: =F17+5 -> 175 | H17: =(F17+G17)/2 -> 172.5 | I17: =SUM(J17:K17) -> 25 | J17: =COUNTIFS(B4:B86,">=170",B4:B86,"<175") -> 15 | K17: =COUNTIFS(D4:D86,">=170",D4:D86,"<175") -> 10 | L17: =I17/$I$22 -> 0.18382353 | M17: =J17/$J$22 -> 0.18072289 | N17: =K17/$K$22 -> 0.18867925 | O17: =O16+L17 -> 0.54411765 | P17: =P16+M17 -> 0.28915663 | Q17: =Q16+N17 -> 0.94339623
A18: Hombre | B18: 175 | C18: Mujer | D18: 185 | F18: =G17 -> 175 | G18: =F18+5 -> 180 | H18: =(F18+G18)/2 -> 177.5 | I18: =SUM(J18:K18) -> 17 | J18: =COUNTIFS(B4:B86,">=175",B4:B86,"<180") -> 16 | K18: =COUNTIFS(D4:D86,">=175",D4:D86,"<180") -> 1 | L18: =I18/$I$22 -> 0.125 | M18: =J18/$J$22 -> 0.19277108 | N18: =K18/$K$22 -> 0.018867925 | O18: =O17+L18 -> 0.66911765 | P18: =P17+M18 -> 0.48192771 | Q18: =Q17+N18 -> 0.96226415
A19: Hombre | B19: 180 | C19: Mujer | D19: 167 | F19: =G18 -> 180 | G19: =F19+5 -> 185 | H19: =(F19+G19)/2 -> 182.5 | I19: =SUM(J19:K19) -> 27 | J19: =COUNTIFS(B4:B86,">=180",B4:B86,"<185") -> 27 | K19: =COUNTIFS(D4:D86,">=180",D4:D86,"<185") -> 0 | L19: =I19/$I$22 -> 0.19852941 | M19: =J19/$J$22 -> 0.3253012 | N19: =K19/$K$22 -> 0 | O19: =O18+L19 -> 0.86764706 | P19: =P18+M19 -> 0.80722892 | Q19: =Q18+N19 -> 0.96226415
A20: Hombre | B20: 185 | C20: Mujer | D20: 165 | F20: =G19 -> 185 | G20: =F20+5 -> 190 | H20: =(F20+G20)/2 -> 187.5 | I20: =SUM(J20:K20) -> 12 | J20: =COUNTIFS(B4:B86,">=185",B4:B86,"<190") -> 10 | K20: =COUNTIFS(D4:D86,">=185",D4:D86,"<190") -> 2 | L20: =I20/$I$22 -> 0.088235294 | M20: =J20/$J$22 -> 0.12048193 | N20: =K20/$K$22 -> 0.037735849 | O20: =O19+L20 -> 0.95588235 | P20: =P19+M20 -> 0.92771084 | Q20: =Q19+N20 -> 1
A21: Hombre | B21: 172 | C21: Mujer | D21: 165 | F21: =G20 -> 190 | G21: =F21+5 -> 195 | H21: =(F21+G21)/2 -> 192.5 | I21: =SUM(J21:K21) -> 6 | J21: =COUNTIFS(B4:B86,">=190",B4:B86,"<195") -> 6 | K21: =COUNTIFS(D4:D86,">=190",D4:D86,"<195") -> 0 | L21: =I21/$I$22 -> 0.044117647 | M21: =J21/$J$22 -> 0.072289157 | N21: =K21/$K$22 -> 0 | O21: =O20+L21 -> 1 | P21: =P20+M21 -> 1 | Q21: =Q20+N21 -> 1
A22: Hombre | B22: 183 | C22: Mujer | D22: 163 | F22: TOTALES | I22: =SUM(I13:I21) -> 136 | J22: =SUM(J13:J21) -> 83 | K22: =SUM(K13:K21) -> 53 | L22: =SUM(L13:L21) -> 1 | M22: =SUM(M13:M21) -> 1 | N22: =SUM(N13:N21) -> 1
A23: Hombre | B23: 180 | C23: Mujer | D23: 165
A24: Hombre | B24: 171 | C24: Mujer | D24: 165
A25: Hombre | B25: 186 | C25: Mujer | D25: 187
A26: Hombre | B26: 187 | C26: Mujer | D26: 175
A27: Hombre | B27: 175 | C27: Mujer | D27: 158
A28: Hombre | B28: 180 | C28: Mujer | D28: 168
A29: Hombre | B29: 180 | C29: Mujer | D29: 162
A30: Hombre | B30: 168 | C30: Mujer | D30: 168
A31: Hombre | B31: 190 | C31: Mujer | D31: 162
A32: Hombre | B32: 169 | C32: Mujer | D32: 158
A33: Hombre | B33: 175 | C33: Mujer | D33: 172
A34: Hombre | B34: 165 | C34: Mujer | D34: 171
... A56: Hombre | B56: 180 | C56: Mujer | D56: 160
A57: Hombre | B57: 186
A58: Hombre | B58: 181
A59: Hombre | B59: 158
A60: Hombre | B60: 178
A61: Hombre | B61: 175
A62: Hombre | B62: 180
A63: Hombre | B63: 182
...

Sheet Gastos
B2: Gasto en alimentación | D2: Número de familias
B3: Li-1 | C3: Li | D3: ni
B4: 150 | C4: 250 | D4: 10
B5: 250 | C5: 350 | D5: 25
B6: 350 | C6: 450 | D6: 50
B7: 450 | C7: 750 | D7: 80
B8: 750 | C8: 1100 | D8: 30
B9: 1100 | C9: 1500 | D9: 5

Sheet Horasred
D13: Li-1 | E13: Li | F13: xi | G13: ni | H13: fi | I13: Ni | J13: Fi
D14: 0 | E14: 7 | F14: =AVERAGE(D14:E14) -> 3.5 | G14: {=FREQUENCY('Datos depurados'!$U$2:$U$143,E14:E22)} -> 62 | H14: =G14/$G$24 -> 0.45588235 | I14: =G14 -> 62 | J14: =H14 -> 0.45588235
A15: Mínimo | B15: =min('Datos depurados'!$U$2:$U$143) -> 0 | D15: 7 | E15: 14 | F15: =AVERAGE(D15:E15) -> 10.5 | G15: 34 | H15: =G15/$G$24 -> 0.25 | I15: =I14+G15 -> 96 | J15: =J14+H15 -> 0.70588235
A16: Máximo | B16: =MAX('Datos depurados'!$U$2:$U$143) -> 70 | D16: 14 | E16: 21 | F16: =AVERAGE(D16:E16) -> 17.5 | G16: 13 | H16: =G16/$G$24 -> 0.095588235 | I16: =I15+G16 -> 109 | J16: =J15+H16 -> 0.80147059
A17: N | B17: =COUNT('Datos depurados'!$U$2:$U$143) -> 136 | D17: 21 | E17: 28 | F17: =AVERAGE(D17:E17) -> 24.5 | G17: 2 | H17: =G17/$G$24 -> 0.014705882 | I17: =I16+G17 -> 111 | J17: =J16+H17 -> 0.81617647
D18: 28 | E18: 35 | F18: =AVERAGE(D18:E18) -> 31.5 | G18: 11 | H18: =G18/$G$24 -> 0.080882353 | I18: =I17+G18 -> 122 | J18: =J17+H18 -> 0.89705882
A19: Número de intervalos | B19: 10 | D19: 35 | E19: 42 | F19: =AVERAGE(D19:E19) -> 38.5 | G19: 0 | H19: =G19/$G$24 -> 0 | I19: =I18+G19 -> 122 | J19: =J18+H19 -> 0.89705882
A20: Amplitud | B20: 7 | D20: 42 | E20: 49 | F20: =AVERAGE(D20:E20) -> 45.5 | G20: 0 | H20: =G20/$G$24 -> 0 | I20: =I19+G20 -> 122 | J20: =J19+H20 -> 0.89705882
D21: 49 | E21: 56 | F21: =AVERAGE(D21:E21) -> 52.5 | G21: 3 | H21: =G21/$G$24 -> 0.022058824 | I21: =I20+G21 -> 125 | J21: =J20+H21 -> 0.91911765
D22: 56 | E22: 63 | F22: =AVERAGE(D22:E22) -> 59.5 | G22: 1 | H22: =G22/$G$24 -> 0.0073529412 | I22: =I21+G22 -> 126 | J22: =J21+H22 -> 0.92647059
D23: 63 | E23: 70 | F23: =AVERAGE(D23:E23) -> 66.5 | G23: 10 | H23: =G23/$G$24 -> 0.073529412 | I23: =I22+G23 -> 136 | J23: =J22+H23 -> 1
D24: TOTALES | G24: =SUM(G14:G23) -> 136 | H24: =SUM(H14:H23) -> 1
D25: PROMEDIOS

Sheet vehículos
A14: 0 | B14: 1 | C14: 3 | D14: 0 | E14: 4 | F14: 4 | G14: 3 | H14: 2 | I14: 3 | J14: 4
A15: 2 | B15: 2 | C15: 0 | D15: 1 | E15: 2 | F15: 3 | G15: 1 | H15: 5 | I15: 3 | J15: 1
A16: 4 | B16: 3 | C16: 4 | D16: 3 | E16: 2 | F16: 3 | G16: 3 | H16: 0 | I16: 3 | J16: 4

Sheet Saldo
A18: Saldo medio trimestral (euros) | B18: Nº clientes
A19: 0-600 | B19: 10
A20: 600-1200 | B20: 15
A21: 1200-1800 | B21: 35
A22: 1800-3000 | B22: 10
A23: 3000-6000 | B23: 5
